<?xml version="1.0" ?>
<!-- =================================================================================== -->
<!-- |    This document was autogenerated by xacro from legs.xacro                     | -->
<!-- |    EDITING THIS FILE BY HAND IS NOT RECOMMENDED                                 | -->
<!-- =================================================================================== -->
<robot name="legs" xmlns:xacro="http://www.ros.org/wiki/xacro">
  <!-- In N*m -->
  <!-- ros_control plugin -->
  <gazebo>
    <plugin filename="libgazebo_ros_control.so" name="gazebo_ros_control">
      <robotNamespace>/legs</robotNamespace>
      <robotSimType>gazebo_ros_control/DefaultRobotHWSim</robotSimType>
    </plugin>
  </gazebo>
  <!-- Bumpers plugins -->
  <gazebo reference="left_foot">
    <sensor name="contact_sensor" type="contact">
      <always_on>true</always_on>
      <update_rate>10</update_rate>
      <contact>
        <collision>left_foot_collision</collision>
        <topic>/left_foot_contact</topic>
      </contact>
      <plugin filename="libgazebo_ros_bumper.so" name="left_foot">
        <frameName>left_foot</frameName>
        <bumperTopicName>/legs/bumper/left_foot</bumperTopicName>
      </plugin>
    </sensor>
  </gazebo>
  <gazebo reference="right_foot">
    <sensor name="contact_sensor" type="contact">
      <always_on>true</always_on>
      <update_rate>10</update_rate>
      <contact>
        <collision>right_foot_collision</collision>
        <topic>/right_foot_contact</topic>
      </contact>
      <plugin filename="libgazebo_ros_bumper.so" name="right_foot">
        <frameName>right_foot</frameName>
        <bumperTopicName>/legs/bumper/right_foot</bumperTopicName>
      </plugin>
    </sensor>
  </gazebo>
  <!-- Starting position -->
  <gazebo>
    <static> false </static>
    <!--       <pose> 0 0 1 0 0 0 </pose> -->
  </gazebo>
  <!-- Links -->
  <gazebo reference="hip">
    <material>Gazebo/Orange</material>
  </gazebo>
  <gazebo reference="left_upper_limb">
    <mu1>0.2</mu1>
    <mu2>0.2</mu2>
    <material>Gazebo/Orange</material>
  </gazebo>
  <gazebo reference="left_lower_limb">
    <mu1>0.2</mu1>
    <mu2>0.2</mu2>
    <material>Gazebo/Orange</material>
  </gazebo>
  <gazebo reference="left_foot">
    <mu1>2.0</mu1>
    <mu2>2.0</mu2>
    <material>Gazebo/Orange</material>
  </gazebo>
  <gazebo reference="right_upper_limb">
    <mu1>0.2</mu1>
    <mu2>0.2</mu2>
    <material>Gazebo/Orange</material>
  </gazebo>
  <gazebo reference="right_lower_limb">
    <mu1>0.2</mu1>
    <mu2>0.2</mu2>
    <material>Gazebo/Orange</material>
  </gazebo>
  <gazebo reference="right_foot">
    <mu1>2.0</mu1>
    <mu2>2.0</mu2>
    <material>Gazebo/Orange</material>
  </gazebo>
  <material name="black">
    <color rgba="0.0 0.0 0.0 1.0"/>
  </material>
  <material name="blue">
    <color rgba="0.0 0.0 0.8 1.0"/>
  </material>
  <material name="green">
    <color rgba="0.0 0.8 0.0 1.0"/>
  </material>
  <material name="grey">
    <color rgba="0.2 0.2 0.2 1.0"/>
  </material>
  <material name="orange">
    <color rgba="1.0 0.423529411765 0.0392156862745 1.0"/>
  </material>
  <material name="brown">
    <color rgba="0.870588235294 0.811764705882 0.764705882353 1.0"/>
  </material>
  <material name="red">
    <color rgba="0.8 0.0 0.0 1.0"/>
  </material>
  <material name="white">
    <color rgba="1.0 1.0 1.0 1.0"/>
  </material>
  <!-- 
		Left Leg
	-->
  <link name="hip">
    <collision>
      <origin rpy="1.57079632679 0 0" xyz="0 0 0"/>
      <geometry>
        <cylinder length="0.180" radius="0.025"/>
      </geometry>
    </collision>
    <visual>
      <origin rpy="0 0 0" xyz="0 0 0"/>
      <geometry>
        <mesh filename="package://legs_description/meshes/iteration_1/gazebo/hip_visual.stl"/>
      </geometry>
      <material name="orange"/>
    </visual>
    <inertial>
      <origin rpy="0 0 0" xyz="0 0 0"/>
      <mass value="0.156"/>
      <inertia ixx="3.03e-004" ixy="0.0" ixz="1.44e-008" iyy="2.78e-005" iyz="0.0" izz="3.14e-004"/>
    </inertial>
  </link>
  <link name="left_upper_limb">
    <collision>
      <origin rpy="1.57079632679 0 0" xyz="0 0.131 0"/>
      <geometry>
        <cylinder length="0.262" radius="0.01"/>
      </geometry>
    </collision>
    <visual>
      <origin rpy="0 0 0" xyz="0 0 0"/>
      <geometry>
        <mesh filename="package://legs_description/meshes/iteration_1/gazebo/left_upper_limb_visual.stl"/>
      </geometry>
      <material name="orange"/>
    </visual>
    <inertial>
      <origin rpy="90 0 0" xyz="0 0 0"/>
      <mass value="0.123"/>
      <inertia ixx="1.19e-003" ixy="2.89e-006" ixz="-1.36e-008" iyy="1.69e-005" iyz="-1.78e-005" izz="1.18e-003"/>
    </inertial>
  </link>
  <link name="left_lower_limb">
    <collision>
      <origin rpy="1.57079632679 0 0" xyz="0 0.131 0"/>
      <geometry>
        <cylinder length="0.212" radius="0.01"/>
      </geometry>
    </collision>
    <visual>
      <origin rpy="0 0 0" xyz="0 0 0"/>
      <geometry>
        <mesh filename="package://legs_description/meshes/iteration_1/gazebo/left_lower_limb_visual.stl"/>
      </geometry>
      <material name="orange"/>
    </visual>
    <inertial>
      <origin rpy="0 0 0" xyz="0 0 0"/>
      <mass value="0.115"/>
      <inertia ixx="6.99e-004" ixy="2.44e-005" ixz="0.0" iyy="1.85e-005" iyz="-1.82e-005" izz="6.94e-004"/>
    </inertial>
  </link>
  <link name="left_foot">
    <collision>
      <origin rpy="0 0 0" xyz="0 0 0"/>
      <geometry>
        <mesh filename="package://legs_description/meshes/iteration_1/gazebo/left_foot_visual.stl"/>
      </geometry>
    </collision>
    <visual>
      <origin rpy="0 0 0" xyz="0 0 0"/>
      <geometry>
        <mesh filename="package://legs_description/meshes/iteration_1/gazebo/left_foot_visual.stl"/>
      </geometry>
      <material name="orange"/>
    </visual>
    <inertial>
      <origin rpy="0 0 0" xyz="0 0 0"/>
      <mass value="0.021"/>
      <inertia ixx="2.2e-005" ixy="-9.16e-006" ixz="0.0" iyy="-9.16e-006" iyz="9.05e-006" izz="2.88e-005"/>
    </inertial>
  </link>
  <link name="right_upper_limb">
    <collision>
      <origin rpy="1.57079632679 0 0" xyz="0 0.131 0"/>
      <geometry>
        <cylinder length="0.262" radius="0.01"/>
      </geometry>
    </collision>
    <visual>
      <origin rpy="0 0 0" xyz="0 0 0"/>
      <geometry>
        <mesh filename="package://legs_description/meshes/iteration_1/gazebo/right_upper_limb_visual.stl"/>
      </geometry>
      <material name="orange"/>
    </visual>
    <inertial>
      <origin rpy="0 0 0" xyz="0 0 0"/>
      <mass value="0.123"/>
      <inertia ixx="1.19e-003" ixy="2.89e-006" ixz="-1.36e-008" iyy="1.69e-005" iyz="-1.78e-005" izz="1.18e-003"/>
    </inertial>
  </link>
  <link name="right_lower_limb">
    <collision>
      <origin rpy="1.57079632679 0 0" xyz="0 0.131 0"/>
      <geometry>
        <cylinder length="0.212" radius="0.01"/>
      </geometry>
    </collision>
    <visual>
      <origin rpy="0 0 0" xyz="0 0 0"/>
      <geometry>
        <mesh filename="package://legs_description/meshes/iteration_1/gazebo/right_lower_limb_visual.stl"/>
      </geometry>
      <material name="orange"/>
    </visual>
    <inertial>
      <origin rpy="0 0 0" xyz="0 0 0"/>
      <mass value="0.115"/>
      <inertia ixx="6.99e-004" ixy="2.44e-005" ixz="0.0" iyy="1.85e-005" iyz="-1.82e-005" izz="6.94e-004"/>
    </inertial>
  </link>
  <link name="right_foot">
    <collision>
      <origin rpy="0 0 0" xyz="0 0 0"/>
      <geometry>
        <mesh filename="package://legs_description/meshes/iteration_1/gazebo/right_foot_visual.stl"/>
      </geometry>
    </collision>
    <visual>
      <origin rpy="0 0 0" xyz="0 0 0"/>
      <geometry>
        <mesh filename="package://legs_description/meshes/iteration_1/gazebo/right_foot_visual.stl"/>
      </geometry>
      <material name="orange"/>
    </visual>
    <inertial>
      <origin rpy="0 0 0" xyz="0 0 0"/>
      <mass value="0.021"/>
      <inertia ixx="2.2e-005" ixy="-9.16e-006" ixz="0.0" iyy="-9.16e-006" iyz="9.05e-006" izz="2.88e-005"/>
    </inertial>
  </link>
  <!-- 
    Virtual links
  -->
  <link name="world"/>
  <!--   <link name="world_pris">
    <inertial>
      <mass value="2e-06"/>
      <inertia ixx="1.1e-09" ixy="0" ixz="0" iyy="1.1e-09" iyz="0" izz="1.1e-09"/>
    </inertial>
  </link>

  <joint name="world_world_pris" type="prismatic">
    <origin xyz="0 0 1" rpy="0 0 0"/>
    <parent link="world"/>
    <child link="world_pris"/>
    <axis xyz="0 0 1"/>
    <limit effort="1000" velocity="1000" lower="0" upper="5" />
  </joint> 

  <joint name="world_pris_hip" type="continuous">
    <origin xyz="0 0 0" rpy="0 0 0"/>
    <parent link="world_pris"/>
    <child link="hip"/>
    <axis xyz="0 1 0"/>
  </joint> -->
  <!-- 
  <joint name="world_hip" type="continuous">
    <origin xyz="0 0 1" rpy="0 0 0"/>
    <parent link="world"/>
    <child link="hip"/>
  </joint>  -->
  <!-- 
		Joints 
	-->
  <joint name="left_hip" type="revolute">
    <parent link="hip"/>
    <child link="left_upper_limb"/>
    <origin rpy="-1.57079632679 0 0" xyz="0 0.0635 -0.028867"/>
    <axis xyz="0 0 -1"/>
    <limit effort="10" lower="-1.0471975512" upper="1.57079632679" velocity="10"/>
    <dynamics damping="0.7"/>
  </joint>
  <joint name="left_knee" type="revolute">
    <parent link="left_upper_limb"/>
    <child link="left_lower_limb"/>
    <origin rpy="0 0 0" xyz="0 0.262 0"/>
    <axis xyz="0 0 -1"/>
    <limit effort="10" lower="-2.09439510239" upper="0.0" velocity="10"/>
    <dynamics damping="0.7"/>
  </joint>
  <joint name="left_ankle" type="revolute">
    <parent link="left_lower_limb"/>
    <child link="left_foot"/>
    <origin rpy="0 0 0" xyz="0 0.212 0"/>
    <axis xyz="0 0 -1"/>
    <limit effort="10" lower="-0.872664625997" upper="2.09439510239" velocity="10"/>
    <dynamics damping="0.7"/>
  </joint>
  <joint name="right_hip" type="revolute">
    <parent link="hip"/>
    <child link="right_upper_limb"/>
    <origin rpy="-1.57079632679 0 0" xyz="0 -0.0635 -0.028867"/>
    <axis xyz="0 0 -1"/>
    <limit effort="10" lower="-1.0471975512" upper="1.57079632679" velocity="10"/>
    <dynamics damping="0.7"/>
  </joint>
  <joint name="right_knee" type="revolute">
    <parent link="right_upper_limb"/>
    <child link="right_lower_limb"/>
    <origin rpy="0 0 0" xyz="0 0.262 0"/>
    <axis xyz="0 0 -1"/>
    <limit effort="10" lower="-2.09439510239" upper="0.0" velocity="10"/>
    <dynamics damping="0.7"/>
  </joint>
  <joint name="right_ankle" type="revolute">
    <parent link="right_lower_limb"/>
    <child link="right_foot"/>
    <origin rpy="0 0 0" xyz="0 0.212 0"/>
    <axis xyz="0 0 -1"/>
    <limit effort="10" lower="-0.872664625997" upper="2.09439510239" velocity="10"/>
    <dynamics damping="0.7"/>
  </joint>
  <transmission name="left_hip_trans">
    <type>transmission_interface/SimpleTransmission</type>
    <joint name="left_hip">
      <hardwareInterface>EffortJointInterface</hardwareInterface>
    </joint>
    <actuator name="left_hip_motor">
      <hardwareInterface>EffortJointInterface</hardwareInterface>
      <mechanicalReduction>1.0787315</mechanicalReduction>
    </actuator>
  </transmission>
  <transmission name="left_knee_trans">
    <type>transmission_interface/SimpleTransmission</type>
    <joint name="left_knee">
      <hardwareInterface>EffortJointInterface</hardwareInterface>
    </joint>
    <actuator name="left_knee_motor">
      <hardwareInterface>EffortJointInterface</hardwareInterface>
      <mechanicalReduction>1.0787315</mechanicalReduction>
    </actuator>
  </transmission>
  <transmission name="left_ankle_trans">
    <type>transmission_interface/SimpleTransmission</type>
    <joint name="left_ankle">
      <hardwareInterface>EffortJointInterface</hardwareInterface>
    </joint>
    <actuator name="left_ankle_motor">
      <hardwareInterface>EffortJointInterface</hardwareInterface>
      <mechanicalReduction>1.0787315</mechanicalReduction>
    </actuator>
  </transmission>
  <transmission name="right_hip_trans">
    <type>transmission_interface/SimpleTransmission</type>
    <joint name="right_hip">
      <hardwareInterface>EffortJointInterface</hardwareInterface>
    </joint>
    <actuator name="right_hip_motor">
      <hardwareInterface>EffortJointInterface</hardwareInterface>
      <mechanicalReduction>1.0787315</mechanicalReduction>
    </actuator>
  </transmission>
  <transmission name="right_knee_trans">
    <type>transmission_interface/SimpleTransmission</type>
    <joint name="right_knee">
      <hardwareInterface>EffortJointInterface</hardwareInterface>
    </joint>
    <actuator name="right_knee_motor">
      <hardwareInterface>EffortJointInterface</hardwareInterface>
      <mechanicalReduction>1.0787315</mechanicalReduction>
    </actuator>
  </transmission>
  <transmission name="right_ankle_trans">
    <type>transmission_interface/SimpleTransmission</type>
    <joint name="right_ankle">
      <hardwareInterface>EffortJointInterface</hardwareInterface>
    </joint>
    <actuator name="right_ankle_motor">
      <hardwareInterface>EffortJointInterface</hardwareInterface>
      <mechanicalReduction>1.0787315</mechanicalReduction>
    </actuator>
  </transmission>
  <!-- <xacro:include filename="$(find gazebo_resources)/models/rotational_robot_holder/urdf/rotational_robot_holder.xacro" /> -->
  <link name="rotational_robot_holder_base">
    <collision>
      <origin rpy="0 0 0" xyz="0 0 0"/>
      <geometry>
        <cylinder length="1" radius="0.2"/>
      </geometry>
    </collision>
    <visual>
      <origin rpy="0 0 0" xyz="0 0 0"/>
      <geometry>
        <cylinder length="1" radius="0.2"/>
      </geometry>
      <material name="orange"/>
    </visual>
    <inertial>
      <mass value="10"/>
      <inertia ixx="0.4" ixy="0.0" ixz="0.0" iyy="0.4" iyz="0.0" izz="0.2"/>
    </inertial>
  </link>
  <link name="rotational_robot_holder_virtual">
    <collision>
      <origin rpy="0 0 0" xyz="0 0 0"/>
      <geometry>
        <sphere radius="0.01"/>
      </geometry>
    </collision>
    <visual>
      <origin rpy="0 0 0" xyz="0 0 0"/>
      <geometry>
        <sphere radius="0.01"/>
      </geometry>
      <material name="orange"/>
    </visual>
    <inertial>
      <mass value="0.01"/>
      <inertia ixx="0.1" ixy="0.0" ixz="0.0" iyy="0.1" iyz="0.0" izz="0.1"/>
    </inertial>
  </link>
  <link name="rotational_robot_holder_holder">
    <collision>
      <origin rpy="0 1.57079632679 0" xyz="1.0 0 0"/>
      <geometry>
        <cylinder length="2" radius="0.01"/>
      </geometry>
    </collision>
    <visual>
      <origin rpy="0 1.57079632679 0" xyz="1.0 0 0"/>
      <geometry>
        <cylinder length="2" radius="0.01"/>
      </geometry>
      <material name="orange"/>
    </visual>
    <inertial>
      <mass value="0.01"/>
      <inertia ixx="0.1" ixy="0.0" ixz="0.0" iyy="0.1" iyz="0.0" izz="0.1"/>
    </inertial>
  </link>
  <!-- Robot to rotational_robot_holder -->
  <joint name="rotational_robot_holder_base_to_world" type="fixed">
    <parent link="world"/>
    <child link="rotational_robot_holder_base"/>
    <origin rpy="0 0 0" xyz="0 0 0.5"/>
  </joint>
  <joint name="rotational_robot_holder_virtual_to_holder" type="continuous">
    <parent link="rotational_robot_holder_base"/>
    <child link="rotational_robot_holder_virtual"/>
    <origin rpy="0 0 0" xyz="0 0 0"/>
    <axis xyz="0 1 0"/>
    <dynamics damping="0.7"/>
  </joint>
  <joint name="rotational_robot_holder_joint" type="continuous">
    <parent link="rotational_robot_holder_virtual"/>
    <child link="rotational_robot_holder_holder"/>
    <origin rpy="0 0 0" xyz="0 0 0.5"/>
    <axis xyz="0 0 1"/>
    <dynamics damping="0.7"/>
  </joint>
  <joint name="rotational_robot_holder_to_rotot" type="fixed">
    <parent link="rotational_robot_holder_holder"/>
    <child link="hip"/>
    <origin rpy="0 0 0" xyz="2.2 0 0"/>
    <axis xyz="0 0 1"/>
    <limit effort="30" lower="0" upper="1" velocity="1.0"/>
  </joint>
</robot>

