<?xml version="1.0" ?>
<!-- =================================================================================== -->
<!-- |    This document was autogenerated by xacro from legs.xacro                     | -->
<!-- |    EDITING THIS FILE BY HAND IS NOT RECOMMENDED                                 | -->
<!-- =================================================================================== -->
<robot name="legs" xmlns:xacro="http://www.ros.org/wiki/xacro">
  <!-- In N*m -->
  <!-- <0.001 doesn't work -->
  <!-- ros_control plugin -->
  <gazebo>
    <plugin filename="libgazebo_ros_control.so" name="gazebo_ros_control">
      <robotNamespace>/legs</robotNamespace>
      <robotSimType>gazebo_ros_control/DefaultRobotHWSim</robotSimType>
    </plugin>
  </gazebo>
  <!-- Bumpers plugins -->
  <gazebo reference="left_foot">
    <sensor name="contact_sensor" type="contact">
      <always_on>true</always_on>
      <update_rate>10</update_rate>
      <contact>
        <collision>left_foot_collision</collision>
        <topic>/left_foot_contact</topic>
      </contact>
      <plugin filename="libgazebo_ros_bumper.so" name="left_foot">
        <frameName>left_foot</frameName>
        <bumperTopicName>/legs/bumper/left_foot</bumperTopicName>
      </plugin>
    </sensor>
  </gazebo>
  <gazebo reference="right_foot">
    <sensor name="contact_sensor" type="contact">
      <always_on>true</always_on>
      <update_rate>10</update_rate>
      <contact>
        <collision>right_foot_collision</collision>
        <topic>/right_foot_contact</topic>
      </contact>
      <plugin filename="libgazebo_ros_bumper.so" name="right_foot">
        <frameName>right_foot</frameName>
        <bumperTopicName>/legs/bumper/right_foot</bumperTopicName>
      </plugin>
    </sensor>
  </gazebo>
  <!-- Starting position -->
  <gazebo>
    <static> false </static>
    <pose> 0 0 0.482 0 0 0 </pose>
  </gazebo>
  <!-- Links -->
  <gazebo reference="body">
    <material>Gazebo/Orange</material>
  </gazebo>
  <gazebo reference="left_upper_leg">
    <mu1>0.2</mu1>
    <mu2>0.2</mu2>
    <material>Gazebo/Orange</material>
  </gazebo>
  <gazebo reference="left_lower_leg">
    <mu1>0.2</mu1>
    <mu2>0.2</mu2>
    <material>Gazebo/Orange</material>
  </gazebo>
  <gazebo reference="left_foot">
    <mu1>2.0</mu1>
    <mu2>2.0</mu2>
    <material>Gazebo/Orange</material>
  </gazebo>
  <gazebo reference="right_upper_leg">
    <mu1>0.2</mu1>
    <mu2>0.2</mu2>
    <material>Gazebo/Orange</material>
  </gazebo>
  <gazebo reference="right_lower_leg">
    <mu1>0.2</mu1>
    <mu2>0.2</mu2>
    <material>Gazebo/Orange</material>
  </gazebo>
  <gazebo reference="right_foot">
    <mu1>2.0</mu1>
    <mu2>2.0</mu2>
    <material>Gazebo/Orange</material>
  </gazebo>
  <material name="black">
    <color rgba="0.0 0.0 0.0 1.0"/>
  </material>
  <material name="blue">
    <color rgba="0.0 0.0 0.8 1.0"/>
  </material>
  <material name="green">
    <color rgba="0.0 0.8 0.0 1.0"/>
  </material>
  <material name="grey">
    <color rgba="0.2 0.2 0.2 1.0"/>
  </material>
  <material name="orange">
    <color rgba="1.0 0.423529411765 0.0392156862745 1.0"/>
  </material>
  <material name="brown">
    <color rgba="0.870588235294 0.811764705882 0.764705882353 1.0"/>
  </material>
  <material name="red">
    <color rgba="0.8 0.0 0.0 1.0"/>
  </material>
  <material name="white">
    <color rgba="1.0 1.0 1.0 1.0"/>
  </material>
  <!-- 
		Macros
	 -->
  <!-- 
		World
	-->
  <!-- <link name="legs_global"/> -->
  <!-- 
		Left Leg
	-->
  <!-- Creates the link -->
  <link name="left_foot">
    <collision>
      <origin rpy="0 -1.57079632679 0" xyz="0.004 0.0325 0"/>
      <geometry>
        <box size="0.015 0.095 0.008"/>
      </geometry>
    </collision>
    <visual>
      <origin rpy="0 -1.57079632679 0" xyz="0.004 0.0325 0"/>
      <geometry>
        <box size="0.015 0.095 0.008"/>
      </geometry>
      <material name="orange"/>
    </visual>
    <inertial>
      <origin rpy="0 -1.57079632679 0" xyz="0.004 0.0325 0"/>
      <mass value="0.0296"/>
      <inertia ixx="0.002" ixy="0.0" ixz="0.0" iyy="0.002" iyz="0.0" izz="0.002"/>
    </inertial>
  </link>
  <!-- Creates the link -->
  <link name="left_lower_leg">
    <collision>
      <origin rpy="0 -1.57079632679 0" xyz="0.106 0 0"/>
      <geometry>
        <box size="0.015 0.015 0.212"/>
      </geometry>
    </collision>
    <visual>
      <origin rpy="0 -1.57079632679 0" xyz="0.106 0 0"/>
      <geometry>
        <box size="0.015 0.015 0.212"/>
      </geometry>
      <material name="orange"/>
    </visual>
    <inertial>
      <origin rpy="0 -1.57079632679 0" xyz="0.106 0 0"/>
      <mass value="0.17"/>
      <inertia ixx="0.002" ixy="0.0" ixz="0.0" iyy="0.002" iyz="0.0" izz="0.002"/>
    </inertial>
  </link>
  <!-- Creates the link -->
  <link name="left_upper_leg">
    <collision>
      <origin rpy="0 -1.57079632679 0" xyz="0.131 0 0"/>
      <geometry>
        <box size="0.015 0.015 0.262"/>
      </geometry>
    </collision>
    <visual>
      <origin rpy="0 -1.57079632679 0" xyz="0.131 0 0"/>
      <geometry>
        <box size="0.015 0.015 0.262"/>
      </geometry>
      <material name="orange"/>
    </visual>
    <inertial>
      <origin rpy="0 -1.57079632679 0" xyz="0.131 0 0"/>
      <mass value="0.163"/>
      <inertia ixx="0.002" ixy="0.0" ixz="0.0" iyy="0.002" iyz="0.0" izz="0.002"/>
    </inertial>
  </link>
  <!-- Creates the link -->
  <link name="right_foot">
    <collision>
      <origin rpy="0 -1.57079632679 0" xyz="0.004 0.0325 0"/>
      <geometry>
        <box size="0.015 0.095 0.008"/>
      </geometry>
    </collision>
    <visual>
      <origin rpy="0 -1.57079632679 0" xyz="0.004 0.0325 0"/>
      <geometry>
        <box size="0.015 0.095 0.008"/>
      </geometry>
      <material name="orange"/>
    </visual>
    <inertial>
      <origin rpy="0 -1.57079632679 0" xyz="0.004 0.0325 0"/>
      <mass value="0.0296"/>
      <inertia ixx="0.002" ixy="0.0" ixz="0.0" iyy="0.002" iyz="0.0" izz="0.002"/>
    </inertial>
  </link>
  <!-- Creates the link -->
  <link name="right_lower_leg">
    <collision>
      <origin rpy="0 -1.57079632679 0" xyz="0.106 0 0"/>
      <geometry>
        <box size="0.015 0.015 0.212"/>
      </geometry>
    </collision>
    <visual>
      <origin rpy="0 -1.57079632679 0" xyz="0.106 0 0"/>
      <geometry>
        <box size="0.015 0.015 0.212"/>
      </geometry>
      <material name="orange"/>
    </visual>
    <inertial>
      <origin rpy="0 -1.57079632679 0" xyz="0.106 0 0"/>
      <mass value="0.17"/>
      <inertia ixx="0.002" ixy="0.0" ixz="0.0" iyy="0.002" iyz="0.0" izz="0.002"/>
    </inertial>
  </link>
  <!-- Creates the link -->
  <link name="right_upper_leg">
    <collision>
      <origin rpy="0 -1.57079632679 0" xyz="0.131 0 0"/>
      <geometry>
        <box size="0.015 0.015 0.262"/>
      </geometry>
    </collision>
    <visual>
      <origin rpy="0 -1.57079632679 0" xyz="0.131 0 0"/>
      <geometry>
        <box size="0.015 0.015 0.262"/>
      </geometry>
      <material name="orange"/>
    </visual>
    <inertial>
      <origin rpy="0 -1.57079632679 0" xyz="0.131 0 0"/>
      <mass value="0.163"/>
      <inertia ixx="0.002" ixy="0.0" ixz="0.0" iyy="0.002" iyz="0.0" izz="0.002"/>
    </inertial>
  </link>
  <!-- Creates the link -->
  <link name="body">
    <collision>
      <origin rpy="0 0 0" xyz="0 0 0.0325"/>
      <geometry>
        <box size="0.17 0.08 0.065"/>
      </geometry>
    </collision>
    <visual>
      <origin rpy="0 0 0" xyz="0 0 0.0325"/>
      <geometry>
        <box size="0.17 0.08 0.065"/>
      </geometry>
      <material name="orange"/>
    </visual>
    <inertial>
      <origin rpy="0 0 0" xyz="0 0 0.0325"/>
      <mass value="0.45"/>
      <inertia ixx="0.002" ixy="0.0" ixz="0.0" iyy="0.002" iyz="0.0" izz="0.002"/>
    </inertial>
  </link>
  <!-- 
    Virtual links
  -->
  <link name="world"/>
  <link name="plane_x">
    <inertial>
      <mass value="2e-06"/>
      <inertia ixx="1.1e-09" ixy="0" ixz="0" iyy="1.1e-09" iyz="0" izz="1.1e-09"/>
    </inertial>
  </link>
  <!-- 
		Joints 
	-->
  <joint name="world_plane_x" type="planar">
    <parent link="world"/>
    <child link="plane_x"/>
    <origin rpy="0 0 0" xyz="0 0 0.482"/>
    <axis xyz="1 0 0"/>
  </joint>
  <joint name="plane_x_body" type="continuous">
    <parent link="plane_x"/>
    <child link="body"/>
    <origin rpy="0 0 0" xyz="0 0 0"/>
    <axis xyz="1 0 0"/>
  </joint>
  <joint name="left_hip" type="revolute">
    <parent link="body"/>
    <child link="left_upper_leg"/>
    <origin rpy="0 1.57079632679 0" xyz="-0.075 0 0"/>
    <axis xyz="0 0 1"/>
    <limit effort="10" lower="-1.3962634016" upper="1.3962634016" velocity="10"/>
    <dynamics damping="0.7"/>
  </joint>
  <joint name="left_knee" type="revolute">
    <parent link="left_upper_leg"/>
    <child link="left_lower_leg"/>
    <origin rpy="0 0 0" xyz="0.262 0 0"/>
    <axis xyz="0 0 1"/>
    <limit effort="10" lower="-2.61799387799" upper="0.0" velocity="10"/>
    <dynamics damping="0.7"/>
  </joint>
  <joint name="left_ankle" type="revolute">
    <parent link="left_lower_leg"/>
    <child link="left_foot"/>
    <origin rpy="0 0 0" xyz="0.212 0 0"/>
    <axis xyz="0 0 1"/>
    <limit effort="10" lower="-0.907571211037" upper="0.663225115758" velocity="10"/>
    <dynamics damping="0.7"/>
  </joint>
  <joint name="right_hip" type="revolute">
    <parent link="body"/>
    <child link="right_upper_leg"/>
    <origin rpy="0 1.57079632679 0" xyz="0.075 0 0"/>
    <axis xyz="0 0 1"/>
    <limit effort="10" lower="-1.3962634016" upper="1.3962634016" velocity="10"/>
    <dynamics damping="0.7"/>
  </joint>
  <joint name="right_knee" type="revolute">
    <parent link="right_upper_leg"/>
    <child link="right_lower_leg"/>
    <origin rpy="0 0 0" xyz="0.262 0 0"/>
    <axis xyz="0 0 1"/>
    <limit effort="10" lower="-2.61799387799" upper="0.0" velocity="10"/>
    <dynamics damping="0.7"/>
  </joint>
  <joint name="right_ankle" type="revolute">
    <parent link="right_lower_leg"/>
    <child link="right_foot"/>
    <origin rpy="0 0 0" xyz="0.212 0 0"/>
    <axis xyz="0 0 1"/>
    <limit effort="10" lower="-0.907571211037" upper="0.663225115758" velocity="10"/>
    <dynamics damping="0.7"/>
  </joint>
  <transmission name="left_hip_trans">
    <type>transmission_interface/SimpleTransmission</type>
    <joint name="left_hip">
      <hardwareInterface>EffortJointInterface</hardwareInterface>
    </joint>
    <actuator name="left_hip_motor">
      <hardwareInterface>EffortJointInterface</hardwareInterface>
      <mechanicalReduction>1.0787315</mechanicalReduction>
    </actuator>
  </transmission>
  <transmission name="left_knee_trans">
    <type>transmission_interface/SimpleTransmission</type>
    <joint name="left_knee">
      <hardwareInterface>EffortJointInterface</hardwareInterface>
    </joint>
    <actuator name="left_knee_motor">
      <hardwareInterface>EffortJointInterface</hardwareInterface>
      <mechanicalReduction>1.0787315</mechanicalReduction>
    </actuator>
  </transmission>
  <transmission name="left_ankle_trans">
    <type>transmission_interface/SimpleTransmission</type>
    <joint name="left_ankle">
      <hardwareInterface>EffortJointInterface</hardwareInterface>
    </joint>
    <actuator name="left_ankle_motor">
      <hardwareInterface>EffortJointInterface</hardwareInterface>
      <mechanicalReduction>1.0787315</mechanicalReduction>
    </actuator>
  </transmission>
  <transmission name="right_hip_trans">
    <type>transmission_interface/SimpleTransmission</type>
    <joint name="right_hip">
      <hardwareInterface>EffortJointInterface</hardwareInterface>
    </joint>
    <actuator name="right_hip_motor">
      <hardwareInterface>EffortJointInterface</hardwareInterface>
      <mechanicalReduction>1.0787315</mechanicalReduction>
    </actuator>
  </transmission>
  <transmission name="right_knee_trans">
    <type>transmission_interface/SimpleTransmission</type>
    <joint name="right_knee">
      <hardwareInterface>EffortJointInterface</hardwareInterface>
    </joint>
    <actuator name="right_knee_motor">
      <hardwareInterface>EffortJointInterface</hardwareInterface>
      <mechanicalReduction>1.0787315</mechanicalReduction>
    </actuator>
  </transmission>
  <transmission name="right_ankle_trans">
    <type>transmission_interface/SimpleTransmission</type>
    <joint name="right_ankle">
      <hardwareInterface>EffortJointInterface</hardwareInterface>
    </joint>
    <actuator name="right_ankle_motor">
      <hardwareInterface>EffortJointInterface</hardwareInterface>
      <mechanicalReduction>1.0787315</mechanicalReduction>
    </actuator>
  </transmission>
  <!-- Rotational robot holder -->
  <!-- 
  <xacro:property name="rotational_robot_holder_base_length_extra" value="0" />
  <xacro:if value="${robot_floating is 1}">
    <xacro:property name="rotational_robot_holder_base_length_extra" value="0.1" />
  </xacro:if>
  <xacro:property name="rotational_robot_holder_base_length" value="${(footHeight + lowerLegHeight + upperLegHeight + rotational_robot_holder_base_length_extra)*scale}" />
  <xacro:property name="rotational_robot_holder_base_radius" value="${0.2*scale}" />
  <xacro:property name="rotational_robot_holder_holder_radius" value="${0.01*scale}" />
  <xacro:property name="rotational_robot_holder_holder_length" value="${2*scale}" />
  <link name="rotational_robot_holder_base">
    <collision>
      <origin xyz="0 0 0" rpy="0 0 0"/>
      <geometry>
        <cylinder length="${rotational_robot_holder_base_length}" radius="${rotational_robot_holder_base_radius}"/>
      </geometry>
    </collision>

    <visual>
      <origin xyz="0 0 0" rpy="0 0 0"/>
      <geometry>
        <cylinder length="${rotational_robot_holder_base_length}" radius="${rotational_robot_holder_base_radius}"/>
      </geometry>
      <material name="orange"/>
    </visual>

    <inertial>
      <mass value="10"/>
      <inertia ixx="0.4" ixy="0.0" ixz="0.0" iyy="0.4" iyz="0.0" izz="0.2"/>
    </inertial>

  </link>

  <link name="rotational_robot_holder_virtual">
    <collision>
      <origin xyz="0 0 0" rpy="0 0 0"/>
      <geometry>
        <sphere radius="0.01"/>
      </geometry>
    </collision>

    <visual>
      <origin xyz="0 0 0" rpy="0 0 0"/>
      <geometry>
         <sphere radius="0.01"/>
      </geometry>
      <material name="orange"/>
    </visual>

    <inertial>
      <mass value="0.01"/>
      <inertia ixx="0.1" ixy="0.0" ixz="0.0" iyy="0.1" iyz="0.0" izz="0.1"/>
    </inertial>
    
  </link>

  <link name="rotational_robot_holder_holder">
    <collision>
      <origin xyz="${rotational_robot_holder_holder_length/2} 0 0" rpy="0 ${PI/2} 0"/>
      <geometry>
        <cylinder length="${rotational_robot_holder_holder_length}" radius="${rotational_robot_holder_holder_radius}"/>
      </geometry>
    </collision>

    <visual>
      <origin xyz="${rotational_robot_holder_holder_length/2} 0 0" rpy="0 ${PI/2} 0"/>
      <geometry>
         <cylinder length="${rotational_robot_holder_holder_length}" radius="${rotational_robot_holder_holder_radius}"/>
      </geometry>
      <material name="orange"/>
    </visual>

    <inertial>
      <mass value="0.01"/>
      <inertia ixx="0.1" ixy="0.0" ixz="0.0" iyy="0.1" iyz="0.0" izz="0.1"/>
    </inertial>
    
  </link>


  <joint name="rotational_robot_holder_base_to_world" type="fixed">
    <parent link="world"/>
    <child link="rotational_robot_holder_base"/>
    <origin xyz="0 0 ${rotational_robot_holder_base_length/2}" rpy="0 0 0"/>
  </joint>


  <xacro:if value="${robot_floating is 1}">
    <joint name="rotational_robot_holder_virtual_to_holder" type="fixed">
      <parent link="rotational_robot_holder_base"/>
      <child link="rotational_robot_holder_virtual"/>
    </joint> 

    <joint name="rotational_robot_holder_joint" type="fixed">
      <parent link="rotational_robot_holder_virtual"/>
      <child link="rotational_robot_holder_holder"/>
      <origin xyz="0 0 ${rotational_robot_holder_base_length/2}" rpy="0 0 0"/>
    </joint>
  </xacro:if>

  <xacro:if value="${robot_floating is 0}">
    <joint name="rotational_robot_holder_virtual_to_holder" type="continuous">
      <parent link="rotational_robot_holder_base"/>
      <child link="rotational_robot_holder_virtual"/>
      <origin xyz="0 0 0" rpy="0 0 0"/>
      <axis xyz="0 1 0"/>
      <dynamics damping="0.7"/>
    </joint> 

    <joint name="rotational_robot_holder_joint" type="continuous">
      <parent link="rotational_robot_holder_virtual"/>
      <child link="rotational_robot_holder_holder"/>
      <origin xyz="0 0 ${rotational_robot_holder_base_length/2}" rpy="0 0 0"/>
      <axis xyz="0 0 1"/>
      <dynamics damping="0.7"/>
    </joint>
  </xacro:if>

  <joint name="rotational_robot_holder_to_rotot" type="fixed">
    <parent link="rotational_robot_holder_holder"/>
    <child link="body"/>
    <origin xyz="${rotational_robot_holder_holder_length+bodyWidth/2} 0 0" rpy="0 0 0"/>
    <axis xyz="0 0 1"/>
    <limit effort="30" velocity="1.0" lower="0" upper="1" />
  </joint> 
 -->
</robot>

