<?xml version="1.0" ?>
<!-- =================================================================================== -->
<!-- |    This document was autogenerated by xacro from dacbot.xacro                   | -->
<!-- |    EDITING THIS FILE BY HAND IS NOT RECOMMENDED                                 | -->
<!-- =================================================================================== -->
<robot name="dacbot" xmlns:xacro="http://www.ros.org/wiki/xacro">
  <material name="black">
    <color rgba="0.0 0.0 0.0 1.0"/>
  </material>
  <material name="blue">
    <color rgba="0.0 0.0 0.8 1.0"/>
  </material>
  <material name="green">
    <color rgba="0.0 0.8 0.0 1.0"/>
  </material>
  <material name="grey">
    <color rgba="0.2 0.2 0.2 1.0"/>
  </material>
  <material name="orange">
    <color rgba="1.0 0.423529411765 0.0392156862745 1.0"/>
  </material>
  <material name="brown">
    <color rgba="0.870588235294 0.811764705882 0.764705882353 1.0"/>
  </material>
  <material name="red">
    <color rgba="0.8 0.0 0.0 1.0"/>
  </material>
  <material name="white">
    <color rgba="1.0 1.0 1.0 1.0"/>
  </material>
  <!-- 
		Macros
	 -->
  <!-- 
		Left Leg
	-->
  <link name="left_foot">
    <collision>
      <origin rpy="0 0 0" xyz="-0.015 0.01 0.004"/>
      <geometry>
        <box size="0.015 0.05 0.008"/>
      </geometry>
    </collision>
    <visual>
      <origin rpy="0 0 0" xyz="-0.015 0.01 0.004"/>
      <geometry>
        <box size="0.015 0.05 0.008"/>
      </geometry>
      <material name="orange"/>
    </visual>
    <inertial>
      <origin rpy="0 0 0" xyz="-0.015 0.01 0.004"/>
      <mass value="0.01"/>
      <inertia ixx="2.13666666667e-06" ixy="0.0" ixz="0.0" iyy="2.40833333333e-07" iyz="0.0" izz="2.27083333333e-06"/>
    </inertial>
  </link>
  <link name="left_lower_leg">
    <collision>
      <origin rpy="0 0 0" xyz="-0.015 0 0.0705"/>
      <geometry>
        <box size="0.015 0.015 0.125"/>
      </geometry>
    </collision>
    <visual>
      <origin rpy="0 0 0" xyz="-0.015 0 0.0705"/>
      <geometry>
        <box size="0.015 0.015 0.125"/>
      </geometry>
      <material name="orange"/>
    </visual>
    <inertial>
      <origin rpy="0 0 0" xyz="-0.015 0 0.0705"/>
      <mass value="0.08"/>
      <inertia ixx="0.000105666666667" ixy="0.0" ixz="0.0" iyy="0.000105666666667" iyz="0.0" izz="3e-06"/>
    </inertial>
  </link>
  <link name="left_upper_leg">
    <collision>
      <origin rpy="0 0 0" xyz="-0.015 0 0.179"/>
      <geometry>
        <box size="0.015 0.015 0.142"/>
      </geometry>
    </collision>
    <visual>
      <origin rpy="0 0 0" xyz="-0.015 0 0.179"/>
      <geometry>
        <box size="0.015 0.015 0.142"/>
      </geometry>
      <material name="orange"/>
    </visual>
    <inertial>
      <origin rpy="0 0 0" xyz="-0.015 0 0.179"/>
      <mass value="0.2"/>
      <inertia ixx="0.000339816666667" ixy="0.0" ixz="0.0" iyy="0.000339816666667" iyz="0.0" izz="7.5e-06"/>
    </inertial>
  </link>
  <link name="right_foot">
    <collision>
      <origin rpy="0 0 0" xyz="0.015 0.01 0.004"/>
      <geometry>
        <box size="0.015 0.05 0.008"/>
      </geometry>
    </collision>
    <visual>
      <origin rpy="0 0 0" xyz="0.015 0.01 0.004"/>
      <geometry>
        <box size="0.015 0.05 0.008"/>
      </geometry>
      <material name="orange"/>
    </visual>
    <inertial>
      <origin rpy="0 0 0" xyz="0.015 0.01 0.004"/>
      <mass value="0.01"/>
      <inertia ixx="2.13666666667e-06" ixy="0.0" ixz="0.0" iyy="2.40833333333e-07" iyz="0.0" izz="2.27083333333e-06"/>
    </inertial>
  </link>
  <link name="right_lower_leg">
    <collision>
      <origin rpy="0 0 0" xyz="0.015 0 0.0705"/>
      <geometry>
        <box size="0.015 0.015 0.125"/>
      </geometry>
    </collision>
    <visual>
      <origin rpy="0 0 0" xyz="0.015 0 0.0705"/>
      <geometry>
        <box size="0.015 0.015 0.125"/>
      </geometry>
      <material name="orange"/>
    </visual>
    <inertial>
      <origin rpy="0 0 0" xyz="0.015 0 0.0705"/>
      <mass value="0.08"/>
      <inertia ixx="0.000105666666667" ixy="0.0" ixz="0.0" iyy="0.000105666666667" iyz="0.0" izz="3e-06"/>
    </inertial>
  </link>
  <link name="right_upper_leg">
    <collision>
      <origin rpy="0 0 0" xyz="0.015 0 0.179"/>
      <geometry>
        <box size="0.015 0.015 0.142"/>
      </geometry>
    </collision>
    <visual>
      <origin rpy="0 0 0" xyz="0.015 0 0.179"/>
      <geometry>
        <box size="0.015 0.015 0.142"/>
      </geometry>
      <material name="orange"/>
    </visual>
    <inertial>
      <origin rpy="0 0 0" xyz="0.015 0 0.179"/>
      <mass value="0.2"/>
      <inertia ixx="0.000339816666667" ixy="0.0" ixz="0.0" iyy="0.000339816666667" iyz="0.0" izz="7.5e-06"/>
    </inertial>
  </link>
  <link name="body">
    <collision>
      <origin rpy="0 0 0" xyz="0 0.0175 0.2625"/>
      <geometry>
        <box size="0.085 0.08 0.065"/>
      </geometry>
    </collision>
    <visual>
      <origin rpy="0 0 0" xyz="0 0.0175 0.2625"/>
      <geometry>
        <box size="0.085 0.08 0.065"/>
      </geometry>
      <material name="orange"/>
    </visual>
    <inertial>
      <origin rpy="0 0 0" xyz="0 0.0175 0.2625"/>
      <mass value="0.45"/>
      <inertia ixx="0.0003984375" ixy="0.0" ixz="0.0" iyy="0.000429375" iyz="0.0" izz="0.0005109375"/>
    </inertial>
  </link>
  <!-- 
		Joints 
	-->
  <!-- Used for fixing robot to Gazebo 'base_link' -->
  <link name="world"/>
  <joint name="world_left_foot" type="floating">
    <parent link="world"/>
    <child link="left_foot"/>
  </joint>
  <joint name="world_right_foot" type="floating">
    <parent link="world"/>
    <child link="right_foot"/>
  </joint>
  <joint name="left_ankle" type="continuous">
    <parent link="left_foot"/>
    <child link="left_lower_leg"/>
    <origin rpy="0 0 0" xyz="-0.015 0 0.004"/>
    <axis xyz="1 0 0"/>
    <dynamics damping="0.7"/>
  </joint>
  <joint name="left_knee" type="fixed">
    <parent link="left_lower_leg"/>
    <child link="left_upper_leg"/>
    <origin rpy="0 0 0" xyz="-0.015 0 0"/>
    <axis xyz="1 0 0"/>
    <dynamics damping="0.7"/>
  </joint>
  <joint name="left_hip" type="continuous">
    <parent link="left_upper_leg"/>
    <child link="body"/>
    <origin rpy="0 0 0" xyz="-0.015 0 0"/>
    <axis xyz="1 0 0"/>
    <dynamics damping="0.7"/>
  </joint>
  <joint name="right_ankle" type="continuous">
    <parent link="right_foot"/>
    <child link="right_lower_leg"/>
    <origin rpy="0 0 0" xyz="-0.015 0 0.004"/>
    <axis xyz="1 0 0"/>
    <dynamics damping="0.7"/>
  </joint>
  <joint name="right_knee" type="fixed">
    <parent link="right_lower_leg"/>
    <child link="right_upper_leg"/>
    <origin rpy="0 0 0" xyz="-0.015 0 0"/>
    <axis xyz="1 0 0"/>
    <dynamics damping="0.7"/>
  </joint>
  <joint name="right_hip" type="continuous">
    <parent link="right_upper_leg"/>
    <child link="body"/>
    <origin rpy="0 0 0" xyz="-0.015 0 0"/>
    <axis xyz="1 0 0"/>
    <dynamics damping="0.7"/>
  </joint>
</robot>

