<sdf version='1.5'>
  <model name='dacbot'>
    <link name='body'>
      <pose frame=''>0 0 0 0 -0 0</pose>
      <inertial>
        <pose frame=''>0 0 0.0325 0 -0 0</pose>
        <mass>0.45</mass>
        <inertia>
          <ixx>0.000398437</ixx>
          <ixy>0</ixy>
          <ixz>0</ixz>
          <iyy>0.000429375</iyy>
          <iyz>0</iyz>
          <izz>0.000510937</izz>
        </inertia>
      </inertial>
      <collision name='body_collision'>
        <pose frame=''>0 0 0.0325 0 -0 0</pose>
        <geometry>
          <box>
            <size>0.085 0.08 0.065</size>
          </box>
        </geometry>
        <surface>
          <contact>
            <ode/>
          </contact>
          <friction>
            <ode/>
          </friction>
        </surface>
      </collision>
      <visual name='body_visual'>
        <pose frame=''>0 0 0.0325 0 -0 0</pose>
        <geometry>
          <box>
            <size>0.085 0.08 0.065</size>
          </box>
        </geometry>
        <material>
          <script>
            <name>Gazebo/Orange</name>
            <uri>file://media/materials/scripts/gazebo.material</uri>
          </script>
        </material>
      </visual>
      <gravity>1</gravity>
      <velocity_decay/>
      <self_collide>0</self_collide>
    </link>
    <link name='left_upper_leg'>
      <pose frame=''>-0.015 0 0 3.14159 1.57079 3.14159</pose>
      <inertial>
        <pose frame=''>0.071 0 0 3.14159 -1.57079 3.14159</pose>
        <mass>0.2</mass>
        <inertia>
          <ixx>0.000339817</ixx>
          <ixy>0</ixy>
          <ixz>0</ixz>
          <iyy>0.000339817</iyy>
          <iyz>0</iyz>
          <izz>7.5e-06</izz>
        </inertia>
      </inertial>
      <collision name='left_upper_leg_collision'>
        <pose frame=''>0.071 0 0 3.14159 -1.57079 3.14159</pose>
        <geometry>
          <box>
            <size>0.015 0.015 0.142</size>
          </box>
        </geometry>
        <surface>
          <contact>
            <ode/>
          </contact>
          <friction>
            <ode>
              <mu>0.2</mu>
              <mu2>0.2</mu2>
            </ode>
          </friction>
        </surface>
      </collision>
      <visual name='left_upper_leg_visual'>
        <pose frame=''>0.071 0 0 3.14159 -1.57079 3.14159</pose>
        <geometry>
          <box>
            <size>0.015 0.015 0.142</size>
          </box>
        </geometry>
        <material>
          <script>
            <name>Gazebo/Orange</name>
            <uri>file://media/materials/scripts/gazebo.material</uri>
          </script>
        </material>
      </visual>
      <gravity>1</gravity>
      <velocity_decay/>
      <self_collide>0</self_collide>
    </link>
    <joint name='left_hip' type='revolute'>
      <child>left_upper_leg</child>
      <parent>body</parent>
      <axis>
        <xyz>1 0 0</xyz>
        <limit>
          <lower>-1e+16</lower>
          <upper>1e+16</upper>
        </limit>
        <dynamics>
          <damping>0.7</damping>
          <friction>0</friction>
          <spring_reference>0</spring_reference>
          <spring_stiffness>0</spring_stiffness>
        </dynamics>
        <use_parent_model_frame>1</use_parent_model_frame>
      </axis>
    </joint>
    <link name='left_lower_leg'>
      <pose frame=''>-0.015 0 -0.142 3.14159 1.57079 3.14159</pose>
      <inertial>
        <pose frame=''>0.0625 0 0 3.14159 -1.57079 3.14159</pose>
        <mass>0.08</mass>
        <inertia>
          <ixx>0.000105667</ixx>
          <ixy>0</ixy>
          <ixz>0</ixz>
          <iyy>0.000105667</iyy>
          <iyz>0</iyz>
          <izz>3e-06</izz>
        </inertia>
      </inertial>
      <collision name='left_lower_leg_collision'>
        <pose frame=''>0.0625 0 0 3.14159 -1.57079 3.14159</pose>
        <geometry>
          <box>
            <size>0.015 0.015 0.125</size>
          </box>
        </geometry>
        <surface>
          <contact>
            <ode/>
          </contact>
          <friction>
            <ode>
              <mu>0.2</mu>
              <mu2>0.2</mu2>
            </ode>
          </friction>
        </surface>
      </collision>
      <visual name='left_lower_leg_visual'>
        <pose frame=''>0.0625 0 0 3.14159 -1.57079 3.14159</pose>
        <geometry>
          <box>
            <size>0.015 0.015 0.125</size>
          </box>
        </geometry>
        <material>
          <script>
            <name>Gazebo/Orange</name>
            <uri>file://media/materials/scripts/gazebo.material</uri>
          </script>
        </material>
      </visual>
      <gravity>1</gravity>
      <velocity_decay/>
      <self_collide>0</self_collide>
    </link>
    <joint name='left_knee' type='revolute'>
      <child>left_lower_leg</child>
      <parent>left_upper_leg</parent>
      <axis>
        <xyz>1 0 0</xyz>
        <limit>
          <lower>-1e+16</lower>
          <upper>1e+16</upper>
        </limit>
        <dynamics>
          <damping>0.7</damping>
          <friction>0</friction>
          <spring_reference>0</spring_reference>
          <spring_stiffness>0</spring_stiffness>
        </dynamics>
        <use_parent_model_frame>1</use_parent_model_frame>
      </axis>
    </joint>
    <link name='left_foot'>
      <pose frame=''>-0.015 0 -0.267 3.14159 1.57079 3.14159</pose>
      <inertial>
        <pose frame=''>0.004 0.01 0 3.14159 -1.57079 3.14159</pose>
        <mass>0.01</mass>
        <inertia>
          <ixx>2.13667e-06</ixx>
          <ixy>0</ixy>
          <ixz>0</ixz>
          <iyy>2.40833e-07</iyy>
          <iyz>0</iyz>
          <izz>2.27083e-06</izz>
        </inertia>
      </inertial>
      <collision name='left_foot_collision'>
        <pose frame=''>0.004 0.01 0 3.14159 -1.57079 3.14159</pose>
        <geometry>
          <box>
            <size>0.015 0.05 0.008</size>
          </box>
        </geometry>
        <surface>
          <contact>
            <ode/>
          </contact>
          <friction>
            <ode>
              <mu>0.2</mu>
              <mu2>0.2</mu2>
            </ode>
          </friction>
        </surface>
      </collision>
      <visual name='left_foot_visual'>
        <pose frame=''>0.004 0.01 0 3.14159 -1.57079 3.14159</pose>
        <geometry>
          <box>
            <size>0.015 0.05 0.008</size>
          </box>
        </geometry>
        <material>
          <script>
            <name>Gazebo/Orange</name>
            <uri>file://media/materials/scripts/gazebo.material</uri>
          </script>
        </material>
      </visual>
      <gravity>1</gravity>
      <velocity_decay/>
      <self_collide>0</self_collide>
    </link>
    <joint name='left_ankle' type='revolute'>
      <child>left_foot</child>
      <parent>left_lower_leg</parent>
      <axis>
        <xyz>1 0 0</xyz>
        <limit>
          <lower>-1e+16</lower>
          <upper>1e+16</upper>
        </limit>
        <dynamics>
          <damping>0.7</damping>
          <friction>0</friction>
          <spring_reference>0</spring_reference>
          <spring_stiffness>0</spring_stiffness>
        </dynamics>
        <use_parent_model_frame>1</use_parent_model_frame>
      </axis>
    </joint>
    <link name='right_upper_leg'>
      <pose frame=''>0.015 0 0 3.14159 1.57079 3.14159</pose>
      <inertial>
        <pose frame=''>0.071 0 0 3.14159 -1.57079 3.14159</pose>
        <mass>0.2</mass>
        <inertia>
          <ixx>0.000339817</ixx>
          <ixy>0</ixy>
          <ixz>0</ixz>
          <iyy>0.000339817</iyy>
          <iyz>0</iyz>
          <izz>7.5e-06</izz>
        </inertia>
      </inertial>
      <collision name='right_upper_leg_collision'>
        <pose frame=''>0.071 0 0 3.14159 -1.57079 3.14159</pose>
        <geometry>
          <box>
            <size>0.015 0.015 0.142</size>
          </box>
        </geometry>
        <surface>
          <contact>
            <ode/>
          </contact>
          <friction>
            <ode>
              <mu>0.2</mu>
              <mu2>0.2</mu2>
            </ode>
          </friction>
        </surface>
      </collision>
      <visual name='right_upper_leg_visual'>
        <pose frame=''>0.071 0 0 3.14159 -1.57079 3.14159</pose>
        <geometry>
          <box>
            <size>0.015 0.015 0.142</size>
          </box>
        </geometry>
        <material>
          <script>
            <name>Gazebo/Orange</name>
            <uri>file://media/materials/scripts/gazebo.material</uri>
          </script>
        </material>
      </visual>
      <gravity>1</gravity>
      <velocity_decay/>
      <self_collide>0</self_collide>
    </link>
    <joint name='right_hip' type='revolute'>
      <child>right_upper_leg</child>
      <parent>body</parent>
      <axis>
        <xyz>1 0 0</xyz>
        <limit>
          <lower>-1e+16</lower>
          <upper>1e+16</upper>
        </limit>
        <dynamics>
          <damping>0.7</damping>
          <friction>0</friction>
          <spring_reference>0</spring_reference>
          <spring_stiffness>0</spring_stiffness>
        </dynamics>
        <use_parent_model_frame>1</use_parent_model_frame>
      </axis>
    </joint>
    <link name='right_lower_leg'>
      <pose frame=''>0.015 0 -0.142 3.14159 1.57079 3.14159</pose>
      <inertial>
        <pose frame=''>0.0625 0 0 3.14159 -1.57079 3.14159</pose>
        <mass>0.08</mass>
        <inertia>
          <ixx>0.000105667</ixx>
          <ixy>0</ixy>
          <ixz>0</ixz>
          <iyy>0.000105667</iyy>
          <iyz>0</iyz>
          <izz>3e-06</izz>
        </inertia>
      </inertial>
      <collision name='right_lower_leg_collision'>
        <pose frame=''>0.0625 0 0 3.14159 -1.57079 3.14159</pose>
        <geometry>
          <box>
            <size>0.015 0.015 0.125</size>
          </box>
        </geometry>
        <surface>
          <contact>
            <ode/>
          </contact>
          <friction>
            <ode>
              <mu>0.2</mu>
              <mu2>0.2</mu2>
            </ode>
          </friction>
        </surface>
      </collision>
      <visual name='right_lower_leg_visual'>
        <pose frame=''>0.0625 0 0 3.14159 -1.57079 3.14159</pose>
        <geometry>
          <box>
            <size>0.015 0.015 0.125</size>
          </box>
        </geometry>
        <material>
          <script>
            <name>Gazebo/Orange</name>
            <uri>file://media/materials/scripts/gazebo.material</uri>
          </script>
        </material>
      </visual>
      <gravity>1</gravity>
      <velocity_decay/>
      <self_collide>0</self_collide>
    </link>
    <joint name='right_knee' type='revolute'>
      <child>right_lower_leg</child>
      <parent>right_upper_leg</parent>
      <axis>
        <xyz>1 0 0</xyz>
        <limit>
          <lower>-1e+16</lower>
          <upper>1e+16</upper>
        </limit>
        <dynamics>
          <damping>0.7</damping>
          <friction>0</friction>
          <spring_reference>0</spring_reference>
          <spring_stiffness>0</spring_stiffness>
        </dynamics>
        <use_parent_model_frame>1</use_parent_model_frame>
      </axis>
    </joint>
    <link name='right_foot'>
      <pose frame=''>0.015 0 -0.267 3.14159 1.57079 3.14159</pose>
      <inertial>
        <pose frame=''>0.004 0.01 0 3.14159 -1.57079 3.14159</pose>
        <mass>0.01</mass>
        <inertia>
          <ixx>2.13667e-06</ixx>
          <ixy>0</ixy>
          <ixz>0</ixz>
          <iyy>2.40833e-07</iyy>
          <iyz>0</iyz>
          <izz>2.27083e-06</izz>
        </inertia>
      </inertial>
      <collision name='right_foot_collision'>
        <pose frame=''>0.004 0.01 0 3.14159 -1.57079 3.14159</pose>
        <geometry>
          <box>
            <size>0.015 0.05 0.008</size>
          </box>
        </geometry>
        <surface>
          <contact>
            <ode/>
          </contact>
          <friction>
            <ode>
              <mu>0.2</mu>
              <mu2>0.2</mu2>
            </ode>
          </friction>
        </surface>
      </collision>
      <visual name='right_foot_visual'>
        <pose frame=''>0.004 0.01 0 3.14159 -1.57079 3.14159</pose>
        <geometry>
          <box>
            <size>0.015 0.05 0.008</size>
          </box>
        </geometry>
        <material>
          <script>
            <name>Gazebo/Orange</name>
            <uri>file://media/materials/scripts/gazebo.material</uri>
          </script>
        </material>
      </visual>
      <gravity>1</gravity>
      <velocity_decay/>
      <self_collide>0</self_collide>
    </link>
    <joint name='right_ankle' type='revolute'>
      <child>right_foot</child>
      <parent>right_lower_leg</parent>
      <axis>
        <xyz>1 0 0</xyz>
        <limit>
          <lower>-1e+16</lower>
          <upper>1e+16</upper>
        </limit>
        <dynamics>
          <damping>0.7</damping>
          <friction>0</friction>
          <spring_reference>0</spring_reference>
          <spring_stiffness>0</spring_stiffness>
        </dynamics>
        <use_parent_model_frame>1</use_parent_model_frame>
      </axis>
    </joint>
    <plugin name='gazebo_ros_control' filename='libgazebo_ros_control.so'>
      <robotNamespace>/dacbot</robotNamespace>
      <robotSimType>gazebo_ros_control/DefaultRobotHWSim</robotSimType>
    </plugin>
    <static>0</static>
    <pose frame=''>0 0 0.5 0 -0 0</pose>
  </model>
</sdf>
