<?xml version="1.0" ?>
<!-- =================================================================================== -->
<!-- |    This document was autogenerated by xacro from dacbot.xacro                   | -->
<!-- |    EDITING THIS FILE BY HAND IS NOT RECOMMENDED                                 | -->
<!-- =================================================================================== -->
<robot name="dacbot" xmlns:xacro="http://www.ros.org/wiki/xacro">
  <!-- In N*m -->
  <!-- <0.001 doesn't work -->
  <!-- ros_control plugin -->
  <gazebo>
    <plugin filename="libgazebo_ros_control.so" name="gazebo_ros_control">
      <robotNamespace>/dacbot</robotNamespace>
      <robotSimType>gazebo_ros_control/DefaultRobotHWSim</robotSimType>
    </plugin>
  </gazebo>
  <!-- Bumpers plugins -->
  <gazebo reference="left_foot">
    <sensor name="contact_sensor" type="contact">
      <always_on>true</always_on>
      <update_rate>10</update_rate>
      <contact>
        <collision>left_foot_collision</collision>
        <topic>/left_foot_contact</topic>
      </contact>
      <plugin filename="libgazebo_ros_bumper.so" name="left_foot">
        <frameName>left_foot</frameName>
        <bumperTopicName>/dacbot/bumper/left_foot</bumperTopicName>
      </plugin>
    </sensor>
  </gazebo>
  <gazebo reference="right_foot">
    <sensor name="contact_sensor" type="contact">
      <always_on>true</always_on>
      <update_rate>10</update_rate>
      <contact>
        <collision>right_foot_collision</collision>
        <topic>/right_foot_contact</topic>
      </contact>
      <plugin filename="libgazebo_ros_bumper.so" name="right_foot">
        <frameName>right_foot</frameName>
        <bumperTopicName>/dacbot/bumper/right_foot</bumperTopicName>
      </plugin>
    </sensor>
  </gazebo>
  <!-- Starting position -->
  <gazebo>
    <static> false </static>
    <pose> 0 0 0.275 0 0 0 </pose>
  </gazebo>
  <!-- Links -->
  <gazebo reference="body">
    <material>Gazebo/Orange</material>
  </gazebo>
  <gazebo reference="left_upper_leg">
    <mu1>0.2</mu1>
    <mu2>0.2</mu2>
    <material>Gazebo/Orange</material>
  </gazebo>
  <gazebo reference="left_lower_leg">
    <mu1>0.2</mu1>
    <mu2>0.2</mu2>
    <material>Gazebo/Orange</material>
  </gazebo>
  <gazebo reference="left_foot">
    <mu1>2.0</mu1>
    <mu2>2.0</mu2>
    <material>Gazebo/Orange</material>
  </gazebo>
  <gazebo reference="right_upper_leg">
    <mu1>0.2</mu1>
    <mu2>0.2</mu2>
    <material>Gazebo/Orange</material>
  </gazebo>
  <gazebo reference="right_lower_leg">
    <mu1>0.2</mu1>
    <mu2>0.2</mu2>
    <material>Gazebo/Orange</material>
  </gazebo>
  <gazebo reference="right_foot">
    <mu1>2.0</mu1>
    <mu2>2.0</mu2>
    <material>Gazebo/Orange</material>
  </gazebo>
  <material name="black">
    <color rgba="0.0 0.0 0.0 1.0"/>
  </material>
  <material name="blue">
    <color rgba="0.0 0.0 0.8 1.0"/>
  </material>
  <material name="green">
    <color rgba="0.0 0.8 0.0 1.0"/>
  </material>
  <material name="grey">
    <color rgba="0.2 0.2 0.2 1.0"/>
  </material>
  <material name="orange">
    <color rgba="1.0 0.423529411765 0.0392156862745 1.0"/>
  </material>
  <material name="brown">
    <color rgba="0.870588235294 0.811764705882 0.764705882353 1.0"/>
  </material>
  <material name="red">
    <color rgba="0.8 0.0 0.0 1.0"/>
  </material>
  <material name="white">
    <color rgba="1.0 1.0 1.0 1.0"/>
  </material>
  <!-- 
		Macros
	 -->
  <!-- 
		World
	-->
  <!-- <link name="dacbot_global"/> -->
  <!-- 
		Left Leg
	-->
  <!-- Creates the link -->
  <link name="left_foot">
    <collision>
      <origin rpy="0 -1.57079632679 0" xyz="0.004 0.01 0"/>
      <geometry>
        <box size="0.015 0.05 0.008"/>
      </geometry>
    </collision>
    <visual>
      <origin rpy="0 -1.57079632679 0" xyz="0.004 0.01 0"/>
      <geometry>
        <box size="0.015 0.05 0.008"/>
      </geometry>
      <material name="orange"/>
    </visual>
    <inertial>
      <origin rpy="0 -1.57079632679 0" xyz="0.004 0.01 0"/>
      <mass value="0.01"/>
      <inertia ixx="0.002" ixy="0.0" ixz="0.0" iyy="0.002" iyz="0.0" izz="0.002"/>
    </inertial>
  </link>
  <!-- Creates the link -->
  <link name="left_lower_leg">
    <collision>
      <origin rpy="0 -1.57079632679 0" xyz="0.0625 0 0"/>
      <geometry>
        <box size="0.015 0.015 0.125"/>
      </geometry>
    </collision>
    <visual>
      <origin rpy="0 -1.57079632679 0" xyz="0.0625 0 0"/>
      <geometry>
        <box size="0.015 0.015 0.125"/>
      </geometry>
      <material name="orange"/>
    </visual>
    <inertial>
      <origin rpy="0 -1.57079632679 0" xyz="0.0625 0 0"/>
      <mass value="0.08"/>
      <inertia ixx="0.002" ixy="0.0" ixz="0.0" iyy="0.002" iyz="0.0" izz="0.002"/>
    </inertial>
  </link>
  <!-- Creates the link -->
  <link name="left_upper_leg">
    <collision>
      <origin rpy="0 -1.57079632679 0" xyz="0.071 0 0"/>
      <geometry>
        <box size="0.015 0.015 0.142"/>
      </geometry>
    </collision>
    <visual>
      <origin rpy="0 -1.57079632679 0" xyz="0.071 0 0"/>
      <geometry>
        <box size="0.015 0.015 0.142"/>
      </geometry>
      <material name="orange"/>
    </visual>
    <inertial>
      <origin rpy="0 -1.57079632679 0" xyz="0.071 0 0"/>
      <mass value="0.2"/>
      <inertia ixx="0.002" ixy="0.0" ixz="0.0" iyy="0.002" iyz="0.0" izz="0.002"/>
    </inertial>
  </link>
  <!-- Creates the link -->
  <link name="right_foot">
    <collision>
      <origin rpy="0 -1.57079632679 0" xyz="0.004 0.01 0"/>
      <geometry>
        <box size="0.015 0.05 0.008"/>
      </geometry>
    </collision>
    <visual>
      <origin rpy="0 -1.57079632679 0" xyz="0.004 0.01 0"/>
      <geometry>
        <box size="0.015 0.05 0.008"/>
      </geometry>
      <material name="orange"/>
    </visual>
    <inertial>
      <origin rpy="0 -1.57079632679 0" xyz="0.004 0.01 0"/>
      <mass value="0.01"/>
      <inertia ixx="0.002" ixy="0.0" ixz="0.0" iyy="0.002" iyz="0.0" izz="0.002"/>
    </inertial>
  </link>
  <!-- Creates the link -->
  <link name="right_lower_leg">
    <collision>
      <origin rpy="0 -1.57079632679 0" xyz="0.0625 0 0"/>
      <geometry>
        <box size="0.015 0.015 0.125"/>
      </geometry>
    </collision>
    <visual>
      <origin rpy="0 -1.57079632679 0" xyz="0.0625 0 0"/>
      <geometry>
        <box size="0.015 0.015 0.125"/>
      </geometry>
      <material name="orange"/>
    </visual>
    <inertial>
      <origin rpy="0 -1.57079632679 0" xyz="0.0625 0 0"/>
      <mass value="0.08"/>
      <inertia ixx="0.002" ixy="0.0" ixz="0.0" iyy="0.002" iyz="0.0" izz="0.002"/>
    </inertial>
  </link>
  <!-- Creates the link -->
  <link name="right_upper_leg">
    <collision>
      <origin rpy="0 -1.57079632679 0" xyz="0.071 0 0"/>
      <geometry>
        <box size="0.015 0.015 0.142"/>
      </geometry>
    </collision>
    <visual>
      <origin rpy="0 -1.57079632679 0" xyz="0.071 0 0"/>
      <geometry>
        <box size="0.015 0.015 0.142"/>
      </geometry>
      <material name="orange"/>
    </visual>
    <inertial>
      <origin rpy="0 -1.57079632679 0" xyz="0.071 0 0"/>
      <mass value="0.2"/>
      <inertia ixx="0.002" ixy="0.0" ixz="0.0" iyy="0.002" iyz="0.0" izz="0.002"/>
    </inertial>
  </link>
  <!-- Creates the link -->
  <link name="body">
    <collision>
      <origin rpy="0 0 0" xyz="0 0 0.0325"/>
      <geometry>
        <box size="0.085 0.08 0.065"/>
      </geometry>
    </collision>
    <visual>
      <origin rpy="0 0 0" xyz="0 0 0.0325"/>
      <geometry>
        <box size="0.085 0.08 0.065"/>
      </geometry>
      <material name="orange"/>
    </visual>
    <inertial>
      <origin rpy="0 0 0" xyz="0 0 0.0325"/>
      <mass value="0.45"/>
      <inertia ixx="0.002" ixy="0.0" ixz="0.0" iyy="0.002" iyz="0.0" izz="0.002"/>
    </inertial>
  </link>
  <!-- 
		Joints 
	-->
  <link name="world"/>
  <!--   <joint name="fixed" type="fixed">
    <parent link="world"/>
    <child link="body"/>
    <origin xyz="0 0 ${(footHeight + lowerLegHeight + upperLegHeight)*1.1}" rpy="0 0 0"/>
  </joint>  -->
  <joint name="left_hip" type="revolute">
    <parent link="body"/>
    <child link="left_upper_leg"/>
    <origin rpy="0 1.57079632679 0" xyz="-0.015 0 0"/>
    <axis xyz="0 0 1"/>
    <limit effort="10" lower="-0.523598775598" upper="0.523598775598" velocity="10"/>
    <dynamics damping="0.7"/>
  </joint>
  <joint name="left_knee" type="revolute">
    <parent link="left_upper_leg"/>
    <child link="left_lower_leg"/>
    <origin rpy="0 0 0" xyz="0.142 0 0"/>
    <axis xyz="0 0 1"/>
    <limit effort="10" lower="-2.61799387799" upper="0.0" velocity="10"/>
    <dynamics damping="0.7"/>
  </joint>
  <joint name="left_ankle" type="revolute">
    <parent link="left_lower_leg"/>
    <child link="left_foot"/>
    <origin rpy="0 0 0" xyz="0.125 0 0"/>
    <axis xyz="0 0 1"/>
    <limit effort="10" lower="0" upper="0" velocity="10"/>
    <dynamics damping="0.7"/>
  </joint>
  <joint name="right_hip" type="revolute">
    <parent link="body"/>
    <child link="right_upper_leg"/>
    <origin rpy="0 1.57079632679 0" xyz="0.015 0 0"/>
    <axis xyz="0 0 1"/>
    <limit effort="10" lower="-0.523598775598" upper="0.523598775598" velocity="10"/>
    <dynamics damping="0.7"/>
  </joint>
  <joint name="right_knee" type="revolute">
    <parent link="right_upper_leg"/>
    <child link="right_lower_leg"/>
    <origin rpy="0 0 0" xyz="0.142 0 0"/>
    <axis xyz="0 0 1"/>
    <limit effort="10" lower="-2.61799387799" upper="0.0" velocity="10"/>
    <dynamics damping="0.7"/>
  </joint>
  <joint name="right_ankle" type="revolute">
    <parent link="right_lower_leg"/>
    <child link="right_foot"/>
    <origin rpy="0 0 0" xyz="0.125 0 0"/>
    <axis xyz="0 0 1"/>
    <limit effort="10" lower="0" upper="0" velocity="10"/>
    <dynamics damping="0.7"/>
  </joint>
  <transmission name="left_hip_trans">
    <type>transmission_interface/SimpleTransmission</type>
    <joint name="left_hip">
      <hardwareInterface>EffortJointInterface</hardwareInterface>
    </joint>
    <actuator name="left_hip_motor">
      <hardwareInterface>EffortJointInterface</hardwareInterface>
      <mechanicalReduction>1.0787315</mechanicalReduction>
    </actuator>
  </transmission>
  <transmission name="left_knee_trans">
    <type>transmission_interface/SimpleTransmission</type>
    <joint name="left_knee">
      <hardwareInterface>EffortJointInterface</hardwareInterface>
    </joint>
    <actuator name="left_knee_motor">
      <hardwareInterface>EffortJointInterface</hardwareInterface>
      <mechanicalReduction>1.0787315</mechanicalReduction>
    </actuator>
  </transmission>
  <transmission name="left_ankle_trans">
    <type>transmission_interface/SimpleTransmission</type>
    <joint name="left_ankle">
      <hardwareInterface>EffortJointInterface</hardwareInterface>
    </joint>
    <actuator name="left_ankle_motor">
      <hardwareInterface>EffortJointInterface</hardwareInterface>
      <mechanicalReduction>1.0787315</mechanicalReduction>
    </actuator>
  </transmission>
  <transmission name="right_hip_trans">
    <type>transmission_interface/SimpleTransmission</type>
    <joint name="right_hip">
      <hardwareInterface>EffortJointInterface</hardwareInterface>
    </joint>
    <actuator name="right_hip_motor">
      <hardwareInterface>EffortJointInterface</hardwareInterface>
      <mechanicalReduction>1.0787315</mechanicalReduction>
    </actuator>
  </transmission>
  <transmission name="right_knee_trans">
    <type>transmission_interface/SimpleTransmission</type>
    <joint name="right_knee">
      <hardwareInterface>EffortJointInterface</hardwareInterface>
    </joint>
    <actuator name="right_knee_motor">
      <hardwareInterface>EffortJointInterface</hardwareInterface>
      <mechanicalReduction>1.0787315</mechanicalReduction>
    </actuator>
  </transmission>
  <transmission name="right_ankle_trans">
    <type>transmission_interface/SimpleTransmission</type>
    <joint name="right_ankle">
      <hardwareInterface>EffortJointInterface</hardwareInterface>
    </joint>
    <actuator name="right_ankle_motor">
      <hardwareInterface>EffortJointInterface</hardwareInterface>
      <mechanicalReduction>1.0787315</mechanicalReduction>
    </actuator>
  </transmission>
  <!-- <xacro:include filename="$(find gazebo_resources)/models/rotational_robot_holder/urdf/rotational_robot_holder.xacro" /> -->
  <link name="rotational_robot_holder_base">
    <collision>
      <origin rpy="0 0 0" xyz="0 0 0"/>
      <geometry>
        <cylinder length="0.375" radius="0.2"/>
      </geometry>
    </collision>
    <visual>
      <origin rpy="0 0 0" xyz="0 0 0"/>
      <geometry>
        <cylinder length="0.375" radius="0.2"/>
      </geometry>
      <material name="orange"/>
    </visual>
    <inertial>
      <mass value="10"/>
      <inertia ixx="0.4" ixy="0.0" ixz="0.0" iyy="0.4" iyz="0.0" izz="0.2"/>
    </inertial>
  </link>
  <link name="rotational_robot_holder_virtual">
    <collision>
      <origin rpy="0 0 0" xyz="0 0 0"/>
      <geometry>
        <sphere radius="0.01"/>
      </geometry>
    </collision>
    <visual>
      <origin rpy="0 0 0" xyz="0 0 0"/>
      <geometry>
        <sphere radius="0.01"/>
      </geometry>
      <material name="orange"/>
    </visual>
    <inertial>
      <mass value="0.01"/>
      <inertia ixx="0.1" ixy="0.0" ixz="0.0" iyy="0.1" iyz="0.0" izz="0.1"/>
    </inertial>
  </link>
  <link name="rotational_robot_holder_holder">
    <collision>
      <origin rpy="0 1.57079632679 0" xyz="1.0 0 0"/>
      <geometry>
        <cylinder length="2" radius="0.01"/>
      </geometry>
    </collision>
    <visual>
      <origin rpy="0 1.57079632679 0" xyz="1.0 0 0"/>
      <geometry>
        <cylinder length="2" radius="0.01"/>
      </geometry>
      <material name="orange"/>
    </visual>
    <inertial>
      <mass value="0.01"/>
      <inertia ixx="0.1" ixy="0.0" ixz="0.0" iyy="0.1" iyz="0.0" izz="0.1"/>
    </inertial>
  </link>
  <!-- Robot to rotational_robot_holder -->
  <joint name="rotational_robot_holder_base_to_world" type="fixed">
    <parent link="world"/>
    <child link="rotational_robot_holder_base"/>
    <origin rpy="0 0 0" xyz="0 0 0.1875"/>
  </joint>
  <joint name="rotational_robot_holder_virtual_to_holder" type="fixed">
    <parent link="rotational_robot_holder_base"/>
    <child link="rotational_robot_holder_virtual"/>
  </joint>
  <joint name="rotational_robot_holder_joint" type="fixed">
    <parent link="rotational_robot_holder_virtual"/>
    <child link="rotational_robot_holder_holder"/>
    <origin rpy="0 0 0" xyz="0 0 0.1875"/>
  </joint>
  <joint name="rotational_robot_holder_to_rotot" type="fixed">
    <parent link="rotational_robot_holder_holder"/>
    <child link="body"/>
    <origin rpy="0 0 0" xyz="2.0425 0 0"/>
    <axis xyz="0 0 1"/>
    <limit effort="30" lower="0" upper="1" velocity="1.0"/>
  </joint>
</robot>

