<?xml version="1.0" ?>
<!-- =================================================================================== -->
<!-- |    This document was autogenerated by xacro from dacbot.xacro                   | -->
<!-- |    EDITING THIS FILE BY HAND IS NOT RECOMMENDED                                 | -->
<!-- =================================================================================== -->
<robot name="dacbot" xmlns:xacro="http://www.ros.org/wiki/xacro">
  <!-- ros_control plugin -->
  <gazebo>
    <plugin filename="libgazebo_ros_control.so" name="gazebo_ros_control">
      <robotNamespace>/dacbot</robotNamespace>
      <robotSimType>gazebo_ros_control/DefaultRobotHWSim</robotSimType>
    </plugin>
  </gazebo>
  <!-- Links -->
  <gazebo>
    <static> false </static>
    <pose> 0 0 8.25 0 0 0 </pose>
  </gazebo>
  <gazebo reference="body">
    <material>Gazebo/Orange</material>
  </gazebo>
  <gazebo reference="left_upper_leg">
    <mu1>0.2</mu1>
    <mu2>0.2</mu2>
    <material>Gazebo/Orange</material>
  </gazebo>
  <gazebo reference="left_lower_leg">
    <mu1>0.2</mu1>
    <mu2>0.2</mu2>
    <material>Gazebo/Orange</material>
  </gazebo>
  <gazebo reference="left_foot">
    <mu1>0.2</mu1>
    <mu2>0.2</mu2>
    <material>Gazebo/Orange</material>
  </gazebo>
  <gazebo reference="right_upper_leg">
    <mu1>0.2</mu1>
    <mu2>0.2</mu2>
    <material>Gazebo/Orange</material>
  </gazebo>
  <gazebo reference="right_lower_leg">
    <mu1>0.2</mu1>
    <mu2>0.2</mu2>
    <material>Gazebo/Orange</material>
  </gazebo>
  <gazebo reference="right_foot">
    <mu1>0.2</mu1>
    <mu2>0.2</mu2>
    <material>Gazebo/Orange</material>
  </gazebo>
  <material name="black">
    <color rgba="0.0 0.0 0.0 1.0"/>
  </material>
  <material name="blue">
    <color rgba="0.0 0.0 0.8 1.0"/>
  </material>
  <material name="green">
    <color rgba="0.0 0.8 0.0 1.0"/>
  </material>
  <material name="grey">
    <color rgba="0.2 0.2 0.2 1.0"/>
  </material>
  <material name="orange">
    <color rgba="1.0 0.423529411765 0.0392156862745 1.0"/>
  </material>
  <material name="brown">
    <color rgba="0.870588235294 0.811764705882 0.764705882353 1.0"/>
  </material>
  <material name="red">
    <color rgba="0.8 0.0 0.0 1.0"/>
  </material>
  <material name="white">
    <color rgba="1.0 1.0 1.0 1.0"/>
  </material>
  <!-- 
		Macros
	 -->
  <!-- 
		World
	-->
  <!-- <link name="dacbot_global"/> -->
  <!-- 
		Left Leg
	-->
  <link name="left_foot">
    <collision>
      <origin rpy="0 -1.57079632679 0" xyz="0.02 0.05 0"/>
      <geometry>
        <box size="0.075 0.25 0.04"/>
      </geometry>
    </collision>
    <visual>
      <origin rpy="0 -1.57079632679 0" xyz="0.02 0.05 0"/>
      <geometry>
        <box size="0.075 0.25 0.04"/>
      </geometry>
      <material name="orange"/>
    </visual>
    <inertial>
      <origin rpy="0 -1.57079632679 0" xyz="0.02 0.05 0"/>
      <mass value="0.05"/>
      <inertia ixx="0.00667708333333" ixy="0.0" ixz="0.0" iyy="0.000752604166667" iyz="0.0" izz="0.00709635416667"/>
    </inertial>
  </link>
  <link name="left_lower_leg">
    <collision>
      <origin rpy="0 -1.57079632679 0" xyz="0.3125 0 0"/>
      <geometry>
        <box size="0.075 0.075 0.625"/>
      </geometry>
    </collision>
    <visual>
      <origin rpy="0 -1.57079632679 0" xyz="0.3125 0 0"/>
      <geometry>
        <box size="0.075 0.075 0.625"/>
      </geometry>
      <material name="orange"/>
    </visual>
    <inertial>
      <origin rpy="0 -1.57079632679 0" xyz="0.3125 0 0"/>
      <mass value="0.4"/>
      <inertia ixx="0.330208333333" ixy="0.0" ixz="0.0" iyy="0.330208333333" iyz="0.0" izz="0.009375"/>
    </inertial>
  </link>
  <link name="left_upper_leg">
    <collision>
      <origin rpy="0 -1.57079632679 0" xyz="0.355 0 0"/>
      <geometry>
        <box size="0.075 0.075 0.71"/>
      </geometry>
    </collision>
    <visual>
      <origin rpy="0 -1.57079632679 0" xyz="0.355 0 0"/>
      <geometry>
        <box size="0.075 0.075 0.71"/>
      </geometry>
      <material name="orange"/>
    </visual>
    <inertial>
      <origin rpy="0 -1.57079632679 0" xyz="0.355 0 0"/>
      <mass value="1.0"/>
      <inertia ixx="1.06192708333" ixy="0.0" ixz="0.0" iyy="1.06192708333" iyz="0.0" izz="0.0234375"/>
    </inertial>
  </link>
  <link name="right_foot">
    <collision>
      <origin rpy="0 -1.57079632679 0" xyz="0.02 0.05 0"/>
      <geometry>
        <box size="0.075 0.25 0.04"/>
      </geometry>
    </collision>
    <visual>
      <origin rpy="0 -1.57079632679 0" xyz="0.02 0.05 0"/>
      <geometry>
        <box size="0.075 0.25 0.04"/>
      </geometry>
      <material name="orange"/>
    </visual>
    <inertial>
      <origin rpy="0 -1.57079632679 0" xyz="0.02 0.05 0"/>
      <mass value="0.05"/>
      <inertia ixx="0.00667708333333" ixy="0.0" ixz="0.0" iyy="0.000752604166667" iyz="0.0" izz="0.00709635416667"/>
    </inertial>
  </link>
  <link name="right_lower_leg">
    <collision>
      <origin rpy="0 -1.57079632679 0" xyz="0.3125 0 0"/>
      <geometry>
        <box size="0.075 0.075 0.625"/>
      </geometry>
    </collision>
    <visual>
      <origin rpy="0 -1.57079632679 0" xyz="0.3125 0 0"/>
      <geometry>
        <box size="0.075 0.075 0.625"/>
      </geometry>
      <material name="orange"/>
    </visual>
    <inertial>
      <origin rpy="0 -1.57079632679 0" xyz="0.3125 0 0"/>
      <mass value="0.4"/>
      <inertia ixx="0.330208333333" ixy="0.0" ixz="0.0" iyy="0.330208333333" iyz="0.0" izz="0.009375"/>
    </inertial>
  </link>
  <link name="right_upper_leg">
    <collision>
      <origin rpy="0 -1.57079632679 0" xyz="0.355 0 0"/>
      <geometry>
        <box size="0.075 0.075 0.71"/>
      </geometry>
    </collision>
    <visual>
      <origin rpy="0 -1.57079632679 0" xyz="0.355 0 0"/>
      <geometry>
        <box size="0.075 0.075 0.71"/>
      </geometry>
      <material name="orange"/>
    </visual>
    <inertial>
      <origin rpy="0 -1.57079632679 0" xyz="0.355 0 0"/>
      <mass value="1.0"/>
      <inertia ixx="1.06192708333" ixy="0.0" ixz="0.0" iyy="1.06192708333" iyz="0.0" izz="0.0234375"/>
    </inertial>
  </link>
  <link name="body">
    <collision>
      <origin rpy="0 0 0" xyz="0 0 0.1625"/>
      <geometry>
        <box size="0.425 0.4 0.325"/>
      </geometry>
    </collision>
    <visual>
      <origin rpy="0 0 0" xyz="0 0 0.1625"/>
      <geometry>
        <box size="0.425 0.4 0.325"/>
      </geometry>
      <material name="orange"/>
    </visual>
    <inertial>
      <origin rpy="0 0 0" xyz="0 0 0.1625"/>
      <mass value="2.25"/>
      <inertia ixx="1.2451171875" ixy="0.0" ixz="0.0" iyy="1.341796875" iyz="0.0" izz="1.5966796875"/>
    </inertial>
  </link>
  <!-- 
		Joints 
	-->
  <joint name="left_hip" type="continuous">
    <parent link="body"/>
    <child link="left_upper_leg"/>
    <origin rpy="0 1.57079632679 0" xyz="-0.075 0 0"/>
    <axis xyz="0 0 1"/>
    <dynamics damping="0.7"/>
  </joint>
  <joint name="left_knee" type="continuous">
    <parent link="left_upper_leg"/>
    <child link="left_lower_leg"/>
    <origin rpy="0 0 0" xyz="0.71 0 0"/>
    <axis xyz="0 0 1"/>
    <dynamics damping="0.7"/>
  </joint>
  <joint name="left_ankle" type="continuous">
    <parent link="left_lower_leg"/>
    <child link="left_foot"/>
    <origin rpy="0 0 0" xyz="0.625 0 0"/>
    <axis xyz="0 0 1"/>
    <dynamics damping="0.7"/>
  </joint>
  <joint name="right_hip" type="continuous">
    <parent link="body"/>
    <child link="right_upper_leg"/>
    <origin rpy="0 1.57079632679 0" xyz="0.075 0 0"/>
    <axis xyz="0 0 1"/>
    <dynamics damping="0.7"/>
  </joint>
  <joint name="right_knee" type="continuous">
    <parent link="right_upper_leg"/>
    <child link="right_lower_leg"/>
    <origin rpy="0 0 0" xyz="0.71 0 0"/>
    <axis xyz="0 0 1"/>
    <dynamics damping="0.7"/>
  </joint>
  <joint name="right_ankle" type="continuous">
    <parent link="right_lower_leg"/>
    <child link="right_foot"/>
    <origin rpy="0 0 0" xyz="0.625 0 0"/>
    <axis xyz="0 0 1"/>
    <dynamics damping="0.7"/>
  </joint>
  <transmission name="left_hip_trans">
    <type>transmission_interface/SimpleTransmission</type>
    <joint name="left_hip">
      <hardwareInterface>EffortJointInterface</hardwareInterface>
    </joint>
    <actuator name="left_hip_motor">
      <hardwareInterface>EffortJointInterface</hardwareInterface>
      <mechanicalReduction>1</mechanicalReduction>
    </actuator>
  </transmission>
  <transmission name="left_knee_trans">
    <type>transmission_interface/SimpleTransmission</type>
    <joint name="left_knee">
      <hardwareInterface>EffortJointInterface</hardwareInterface>
    </joint>
    <actuator name="left_knee_motor">
      <hardwareInterface>EffortJointInterface</hardwareInterface>
      <mechanicalReduction>1</mechanicalReduction>
    </actuator>
  </transmission>
  <transmission name="left_ankle_trans">
    <type>transmission_interface/SimpleTransmission</type>
    <joint name="left_ankle">
      <hardwareInterface>EffortJointInterface</hardwareInterface>
    </joint>
    <actuator name="left_ankle_motor">
      <hardwareInterface>EffortJointInterface</hardwareInterface>
      <mechanicalReduction>1</mechanicalReduction>
    </actuator>
  </transmission>
  <transmission name="right_hip_trans">
    <type>transmission_interface/SimpleTransmission</type>
    <joint name="right_hip">
      <hardwareInterface>EffortJointInterface</hardwareInterface>
    </joint>
    <actuator name="right_hip_motor">
      <hardwareInterface>EffortJointInterface</hardwareInterface>
      <mechanicalReduction>1</mechanicalReduction>
    </actuator>
  </transmission>
  <transmission name="right_knee_trans">
    <type>transmission_interface/SimpleTransmission</type>
    <joint name="right_knee">
      <hardwareInterface>EffortJointInterface</hardwareInterface>
    </joint>
    <actuator name="right_knee_motor">
      <hardwareInterface>EffortJointInterface</hardwareInterface>
      <mechanicalReduction>1</mechanicalReduction>
    </actuator>
  </transmission>
  <transmission name="right_ankle_trans">
    <type>transmission_interface/SimpleTransmission</type>
    <joint name="right_ankle">
      <hardwareInterface>EffortJointInterface</hardwareInterface>
    </joint>
    <actuator name="right_ankle_motor">
      <hardwareInterface>EffortJointInterface</hardwareInterface>
      <mechanicalReduction>1</mechanicalReduction>
    </actuator>
  </transmission>
</robot>

